2019-26-26 17:26:25-__init__-DEBUG-Using selector: SelectSelector
2019-26-26 17:26:48-__init__-DEBUG-Using selector: SelectSelector
2019-27-26 17:27:29-__init__-DEBUG-Using selector: SelectSelector
2019-27-26 17:27:40-__init__-DEBUG-Using selector: SelectSelector
2019-27-26 17:27:50-__init__-DEBUG-Using selector: SelectSelector
2019-28-26 17:28:56-__init__-DEBUG-Using selector: SelectSelector
2019-29-26 17:29:03-__init__-DEBUG-Using selector: SelectSelector
2019-27-27 11:27:27-trigger_reload-INFO-D:\Study\School\e2e\app\djangoapp\backend\views.py changed, reloading.
2019-27-27 11:27:27-__init__-DEBUG-Using selector: SelectSelector
2019-28-27 11:28:24-trigger_reload-INFO-D:\Study\School\e2e\app\djangoapp\backend\views.py changed, reloading.
2019-28-27 11:28:24-__init__-DEBUG-Using selector: SelectSelector
2019-28-27 11:28:45-trigger_reload-INFO-D:\Study\School\e2e\app\djangoapp\backend\views.py changed, reloading.
2019-28-27 11:28:45-__init__-DEBUG-Using selector: SelectSelector
2019-29-27 11:29:28-trigger_reload-INFO-D:\Study\School\e2e\app\djangoapp\backend\views.py changed, reloading.
2019-29-27 11:29:28-__init__-DEBUG-Using selector: SelectSelector
2019-31-27 11:31:09-trigger_reload-INFO-D:\Study\School\e2e\app\djangoapp\backend\views.py changed, reloading.
2019-31-27 11:31:09-__init__-DEBUG-Using selector: SelectSelector
2019-31-27 11:31:33-trigger_reload-INFO-D:\Study\School\e2e\app\djangoapp\backend\urls.py changed, reloading.
2019-31-27 11:31:33-__init__-DEBUG-Using selector: SelectSelector
2019-31-27 11:31:41-trigger_reload-INFO-D:\Study\School\e2e\app\djangoapp\backend\urls.py changed, reloading.
2019-31-27 11:31:41-__init__-DEBUG-Using selector: SelectSelector
2019-31-27 11:31:57-trigger_reload-INFO-D:\Study\School\e2e\app\djangoapp\backend\urls.py changed, reloading.
2019-31-27 11:31:57-__init__-DEBUG-Using selector: SelectSelector
2019-32-27 11:32:06-trigger_reload-INFO-D:\Study\School\e2e\app\djangoapp\backend\urls.py changed, reloading.
2019-32-27 11:32:06-__init__-DEBUG-Using selector: SelectSelector
2019-32-27 11:32:11-trigger_reload-INFO-D:\Study\School\e2e\app\djangoapp\backend\urls.py changed, reloading.
2019-32-27 11:32:11-__init__-DEBUG-Using selector: SelectSelector
2019-32-27 11:32:29-trigger_reload-INFO-D:\Study\School\e2e\app\djangoapp\backend\urls.py changed, reloading.
2019-32-27 11:32:29-__init__-DEBUG-Using selector: SelectSelector
2019-32-27 11:32:58-trigger_reload-INFO-D:\Study\School\e2e\app\djangoapp\backend\urls.py changed, reloading.
2019-32-27 11:32:58-__init__-DEBUG-Using selector: SelectSelector
2019-33-27 11:33:01-trigger_reload-INFO-D:\Study\School\e2e\app\djangoapp\djangoapp\urls.py changed, reloading.
2019-33-27 11:33:01-__init__-DEBUG-Using selector: SelectSelector
2019-34-27 11:34:24-trigger_reload-INFO-D:\Study\School\e2e\app\djangoapp\backend\urls.py changed, reloading.
2019-34-27 11:34:24-__init__-DEBUG-Using selector: SelectSelector
2019-34-27 11:34:46-trigger_reload-INFO-D:\Study\School\e2e\app\djangoapp\djangoapp\settings.py changed, reloading.
2019-34-27 11:34:46-__init__-DEBUG-Using selector: SelectSelector
2019-34-27 11:34:49-trigger_reload-INFO-D:\Study\School\e2e\app\djangoapp\djangoapp\settings.py changed, reloading.
2019-34-27 11:34:49-__init__-DEBUG-Using selector: SelectSelector
2019-34-27 11:34:56-trigger_reload-INFO-D:\Study\School\e2e\app\djangoapp\backend\urls.py changed, reloading.
2019-34-27 11:34:56-__init__-DEBUG-Using selector: SelectSelector
2019-35-27 11:35:00-__init__-DEBUG-Using selector: SelectSelector
2019-35-27 11:35:05-log_response-WARNING-Not Found: /favicon.ico
2019-35-27 11:35:24-log_response-WARNING-Not Found: /apis/users
2019-35-27 11:35:33-log_response-WARNING-Not Found: /users
2019-39-27 11:39:11-trigger_reload-INFO-D:\Study\School\e2e\app\djangoapp\backend\urls.py changed, reloading.
2019-39-27 11:39:11-__init__-DEBUG-Using selector: SelectSelector
2019-39-27 11:39:14-trigger_reload-INFO-D:\Study\School\e2e\app\djangoapp\djangoapp\urls.py changed, reloading.
2019-39-27 11:39:14-__init__-DEBUG-Using selector: SelectSelector
2019-39-27 11:39:17-trigger_reload-INFO-D:\Study\School\e2e\app\djangoapp\djangoapp\urls.py changed, reloading.
2019-39-27 11:39:17-__init__-DEBUG-Using selector: SelectSelector
2019-39-27 11:39:30-trigger_reload-INFO-D:\Study\School\e2e\app\djangoapp\backend\urls.py changed, reloading.
2019-39-27 11:39:30-__init__-DEBUG-Using selector: SelectSelector
2019-40-27 11:40:15-trigger_reload-INFO-D:\Study\School\e2e\app\djangoapp\backend\urls.py changed, reloading.
2019-40-27 11:40:15-__init__-DEBUG-Using selector: SelectSelector
2019-40-27 11:40:22-log_response-ERROR-Internal Server Error: /apis/users/
Traceback (most recent call last):
  File "C:\Users\Pisho\AppData\Roaming\Python\Python37\site-packages\django\core\handlers\exception.py", line 34, in inner
    response = get_response(request)
  File "C:\Users\Pisho\AppData\Roaming\Python\Python37\site-packages\django\core\handlers\base.py", line 115, in _get_response
    response = self.process_exception_by_middleware(e, request)
  File "C:\Users\Pisho\AppData\Roaming\Python\Python37\site-packages\django\core\handlers\base.py", line 113, in _get_response
    response = wrapped_callback(request, *callback_args, **callback_kwargs)
  File "C:\Users\Pisho\AppData\Roaming\Python\Python37\site-packages\django\views\decorators\csrf.py", line 54, in wrapped_view
    return view_func(*args, **kwargs)
  File "C:\Users\Pisho\AppData\Local\Programs\Python\Python37\lib\site-packages\rest_framework\viewsets.py", line 114, in view
    return self.dispatch(request, *args, **kwargs)
  File "C:\Users\Pisho\AppData\Local\Programs\Python\Python37\lib\site-packages\rest_framework\views.py", line 505, in dispatch
    response = self.handle_exception(exc)
  File "C:\Users\Pisho\AppData\Local\Programs\Python\Python37\lib\site-packages\rest_framework\views.py", line 465, in handle_exception
    self.raise_uncaught_exception(exc)
  File "C:\Users\Pisho\AppData\Local\Programs\Python\Python37\lib\site-packages\rest_framework\views.py", line 476, in raise_uncaught_exception
    raise exc
  File "C:\Users\Pisho\AppData\Local\Programs\Python\Python37\lib\site-packages\rest_framework\views.py", line 502, in dispatch
    response = handler(request, *args, **kwargs)
  File "C:\Users\Pisho\AppData\Local\Programs\Python\Python37\lib\site-packages\rest_framework\mixins.py", line 43, in list
    return self.get_paginated_response(serializer.data)
  File "C:\Users\Pisho\AppData\Local\Programs\Python\Python37\lib\site-packages\rest_framework\serializers.py", line 760, in data
    ret = super().data
  File "C:\Users\Pisho\AppData\Local\Programs\Python\Python37\lib\site-packages\rest_framework\serializers.py", line 260, in data
    self._data = self.to_representation(self.instance)
  File "C:\Users\Pisho\AppData\Local\Programs\Python\Python37\lib\site-packages\rest_framework\serializers.py", line 678, in to_representation
    self.child.to_representation(item) for item in iterable
  File "C:\Users\Pisho\AppData\Local\Programs\Python\Python37\lib\site-packages\rest_framework\serializers.py", line 678, in <listcomp>
    self.child.to_representation(item) for item in iterable
  File "C:\Users\Pisho\AppData\Local\Programs\Python\Python37\lib\site-packages\rest_framework\serializers.py", line 514, in to_representation
    for field in fields:
  File "C:\Users\Pisho\AppData\Local\Programs\Python\Python37\lib\site-packages\rest_framework\serializers.py", line 375, in _readable_fields
    for field in self.fields.values():
  File "C:\Users\Pisho\AppData\Roaming\Python\Python37\site-packages\django\utils\functional.py", line 48, in __get__
    res = instance.__dict__[self.name] = self.func(instance)
  File "C:\Users\Pisho\AppData\Local\Programs\Python\Python37\lib\site-packages\rest_framework\serializers.py", line 363, in fields
    for key, value in self.get_fields().items():
  File "C:\Users\Pisho\AppData\Local\Programs\Python\Python37\lib\site-packages\rest_framework\serializers.py", line 1063, in get_fields
    source, info, model, depth
  File "C:\Users\Pisho\AppData\Local\Programs\Python\Python37\lib\site-packages\rest_framework\serializers.py", line 1208, in build_field
    return self.build_unknown_field(field_name, model_class)
  File "C:\Users\Pisho\AppData\Local\Programs\Python\Python37\lib\site-packages\rest_framework\serializers.py", line 1325, in build_unknown_field
    (field_name, model_class.__name__)
django.core.exceptions.ImproperlyConfigured: Field name `userid` is not valid for model `User`.
2019-40-27 11:40:48-trigger_reload-INFO-D:\Study\School\e2e\app\djangoapp\backend\serializers.py changed, reloading.
2019-40-27 11:40:48-__init__-DEBUG-Using selector: SelectSelector
2019-40-27 11:40:51-trigger_reload-INFO-D:\Study\School\e2e\app\djangoapp\backend\serializers.py changed, reloading.
2019-40-27 11:40:51-__init__-DEBUG-Using selector: SelectSelector
2019-40-27 11:40:59-trigger_reload-INFO-D:\Study\School\e2e\app\djangoapp\backend\serializers.py changed, reloading.
2019-40-27 11:40:59-__init__-DEBUG-Using selector: SelectSelector
2019-41-27 11:41:01-trigger_reload-INFO-D:\Study\School\e2e\app\djangoapp\backend\serializers.py changed, reloading.
2019-41-27 11:41:01-__init__-DEBUG-Using selector: SelectSelector
2019-41-27 11:41:06-trigger_reload-INFO-D:\Study\School\e2e\app\djangoapp\backend\serializers.py changed, reloading.
2019-41-27 11:41:06-__init__-DEBUG-Using selector: SelectSelector
2019-41-27 11:41:08-trigger_reload-INFO-D:\Study\School\e2e\app\djangoapp\backend\serializers.py changed, reloading.
2019-41-27 11:41:08-__init__-DEBUG-Using selector: SelectSelector
2019-41-27 11:41:15-trigger_reload-INFO-D:\Study\School\e2e\app\djangoapp\backend\serializers.py changed, reloading.
2019-41-27 11:41:15-__init__-DEBUG-Using selector: SelectSelector
2019-41-27 11:41:18-trigger_reload-INFO-D:\Study\School\e2e\app\djangoapp\backend\serializers.py changed, reloading.
2019-41-27 11:41:18-__init__-DEBUG-Using selector: SelectSelector
2019-41-27 11:41:30-log_response-ERROR-Internal Server Error: /apis/users/
Traceback (most recent call last):
  File "C:\Users\Pisho\AppData\Roaming\Python\Python37\site-packages\django\core\handlers\exception.py", line 34, in inner
    response = get_response(request)
  File "C:\Users\Pisho\AppData\Roaming\Python\Python37\site-packages\django\core\handlers\base.py", line 115, in _get_response
    response = self.process_exception_by_middleware(e, request)
  File "C:\Users\Pisho\AppData\Roaming\Python\Python37\site-packages\django\core\handlers\base.py", line 113, in _get_response
    response = wrapped_callback(request, *callback_args, **callback_kwargs)
  File "C:\Users\Pisho\AppData\Roaming\Python\Python37\site-packages\django\views\decorators\csrf.py", line 54, in wrapped_view
    return view_func(*args, **kwargs)
  File "C:\Users\Pisho\AppData\Local\Programs\Python\Python37\lib\site-packages\rest_framework\viewsets.py", line 114, in view
    return self.dispatch(request, *args, **kwargs)
  File "C:\Users\Pisho\AppData\Local\Programs\Python\Python37\lib\site-packages\rest_framework\views.py", line 505, in dispatch
    response = self.handle_exception(exc)
  File "C:\Users\Pisho\AppData\Local\Programs\Python\Python37\lib\site-packages\rest_framework\views.py", line 465, in handle_exception
    self.raise_uncaught_exception(exc)
  File "C:\Users\Pisho\AppData\Local\Programs\Python\Python37\lib\site-packages\rest_framework\views.py", line 476, in raise_uncaught_exception
    raise exc
  File "C:\Users\Pisho\AppData\Local\Programs\Python\Python37\lib\site-packages\rest_framework\views.py", line 502, in dispatch
    response = handler(request, *args, **kwargs)
  File "C:\Users\Pisho\AppData\Local\Programs\Python\Python37\lib\site-packages\rest_framework\mixins.py", line 43, in list
    return self.get_paginated_response(serializer.data)
  File "C:\Users\Pisho\AppData\Local\Programs\Python\Python37\lib\site-packages\rest_framework\serializers.py", line 760, in data
    ret = super().data
  File "C:\Users\Pisho\AppData\Local\Programs\Python\Python37\lib\site-packages\rest_framework\serializers.py", line 260, in data
    self._data = self.to_representation(self.instance)
  File "C:\Users\Pisho\AppData\Local\Programs\Python\Python37\lib\site-packages\rest_framework\serializers.py", line 678, in to_representation
    self.child.to_representation(item) for item in iterable
  File "C:\Users\Pisho\AppData\Local\Programs\Python\Python37\lib\site-packages\rest_framework\serializers.py", line 678, in <listcomp>
    self.child.to_representation(item) for item in iterable
  File "C:\Users\Pisho\AppData\Local\Programs\Python\Python37\lib\site-packages\rest_framework\serializers.py", line 514, in to_representation
    for field in fields:
  File "C:\Users\Pisho\AppData\Local\Programs\Python\Python37\lib\site-packages\rest_framework\serializers.py", line 375, in _readable_fields
    for field in self.fields.values():
  File "C:\Users\Pisho\AppData\Roaming\Python\Python37\site-packages\django\utils\functional.py", line 48, in __get__
    res = instance.__dict__[self.name] = self.func(instance)
  File "C:\Users\Pisho\AppData\Local\Programs\Python\Python37\lib\site-packages\rest_framework\serializers.py", line 363, in fields
    for key, value in self.get_fields().items():
  File "C:\Users\Pisho\AppData\Local\Programs\Python\Python37\lib\site-packages\rest_framework\serializers.py", line 1063, in get_fields
    source, info, model, depth
  File "C:\Users\Pisho\AppData\Local\Programs\Python\Python37\lib\site-packages\rest_framework\serializers.py", line 1208, in build_field
    return self.build_unknown_field(field_name, model_class)
  File "C:\Users\Pisho\AppData\Local\Programs\Python\Python37\lib\site-packages\rest_framework\serializers.py", line 1325, in build_unknown_field
    (field_name, model_class.__name__)
django.core.exceptions.ImproperlyConfigured: Field name `userid` is not valid for model `User`.
2019-42-27 11:42:20-trigger_reload-INFO-D:\Study\School\e2e\app\djangoapp\backend\serializers.py changed, reloading.
2019-42-27 11:42:20-__init__-DEBUG-Using selector: SelectSelector
2019-42-27 11:42:22-log_response-ERROR-Internal Server Error: /apis/users/
Traceback (most recent call last):
  File "C:\Users\Pisho\AppData\Roaming\Python\Python37\site-packages\django\core\handlers\exception.py", line 34, in inner
    response = get_response(request)
  File "C:\Users\Pisho\AppData\Roaming\Python\Python37\site-packages\django\core\handlers\base.py", line 115, in _get_response
    response = self.process_exception_by_middleware(e, request)
  File "C:\Users\Pisho\AppData\Roaming\Python\Python37\site-packages\django\core\handlers\base.py", line 113, in _get_response
    response = wrapped_callback(request, *callback_args, **callback_kwargs)
  File "C:\Users\Pisho\AppData\Roaming\Python\Python37\site-packages\django\views\decorators\csrf.py", line 54, in wrapped_view
    return view_func(*args, **kwargs)
  File "C:\Users\Pisho\AppData\Local\Programs\Python\Python37\lib\site-packages\rest_framework\viewsets.py", line 114, in view
    return self.dispatch(request, *args, **kwargs)
  File "C:\Users\Pisho\AppData\Local\Programs\Python\Python37\lib\site-packages\rest_framework\views.py", line 505, in dispatch
    response = self.handle_exception(exc)
  File "C:\Users\Pisho\AppData\Local\Programs\Python\Python37\lib\site-packages\rest_framework\views.py", line 465, in handle_exception
    self.raise_uncaught_exception(exc)
  File "C:\Users\Pisho\AppData\Local\Programs\Python\Python37\lib\site-packages\rest_framework\views.py", line 476, in raise_uncaught_exception
    raise exc
  File "C:\Users\Pisho\AppData\Local\Programs\Python\Python37\lib\site-packages\rest_framework\views.py", line 502, in dispatch
    response = handler(request, *args, **kwargs)
  File "C:\Users\Pisho\AppData\Local\Programs\Python\Python37\lib\site-packages\rest_framework\mixins.py", line 43, in list
    return self.get_paginated_response(serializer.data)
  File "C:\Users\Pisho\AppData\Local\Programs\Python\Python37\lib\site-packages\rest_framework\serializers.py", line 760, in data
    ret = super().data
  File "C:\Users\Pisho\AppData\Local\Programs\Python\Python37\lib\site-packages\rest_framework\serializers.py", line 260, in data
    self._data = self.to_representation(self.instance)
  File "C:\Users\Pisho\AppData\Local\Programs\Python\Python37\lib\site-packages\rest_framework\serializers.py", line 678, in to_representation
    self.child.to_representation(item) for item in iterable
  File "C:\Users\Pisho\AppData\Local\Programs\Python\Python37\lib\site-packages\rest_framework\serializers.py", line 678, in <listcomp>
    self.child.to_representation(item) for item in iterable
  File "C:\Users\Pisho\AppData\Local\Programs\Python\Python37\lib\site-packages\rest_framework\serializers.py", line 514, in to_representation
    for field in fields:
  File "C:\Users\Pisho\AppData\Local\Programs\Python\Python37\lib\site-packages\rest_framework\serializers.py", line 375, in _readable_fields
    for field in self.fields.values():
  File "C:\Users\Pisho\AppData\Roaming\Python\Python37\site-packages\django\utils\functional.py", line 48, in __get__
    res = instance.__dict__[self.name] = self.func(instance)
  File "C:\Users\Pisho\AppData\Local\Programs\Python\Python37\lib\site-packages\rest_framework\serializers.py", line 363, in fields
    for key, value in self.get_fields().items():
  File "C:\Users\Pisho\AppData\Local\Programs\Python\Python37\lib\site-packages\rest_framework\serializers.py", line 1063, in get_fields
    source, info, model, depth
  File "C:\Users\Pisho\AppData\Local\Programs\Python\Python37\lib\site-packages\rest_framework\serializers.py", line 1208, in build_field
    return self.build_unknown_field(field_name, model_class)
  File "C:\Users\Pisho\AppData\Local\Programs\Python\Python37\lib\site-packages\rest_framework\serializers.py", line 1325, in build_unknown_field
    (field_name, model_class.__name__)
django.core.exceptions.ImproperlyConfigured: Field name `IdentityPub` is not valid for model `User`.
2019-42-27 11:42:47-trigger_reload-INFO-D:\Study\School\e2e\app\djangoapp\backend\serializers.py changed, reloading.
2019-42-27 11:42:47-__init__-DEBUG-Using selector: SelectSelector
2019-42-27 11:42:51-trigger_reload-INFO-D:\Study\School\e2e\app\djangoapp\backend\serializers.py changed, reloading.
2019-42-27 11:42:51-__init__-DEBUG-Using selector: SelectSelector
2019-42-27 11:42:54-trigger_reload-INFO-D:\Study\School\e2e\app\djangoapp\backend\serializers.py changed, reloading.
2019-42-27 11:42:54-__init__-DEBUG-Using selector: SelectSelector
2019-43-27 11:43:48-log_response-ERROR-Internal Server Error: /apis/users/
Traceback (most recent call last):
  File "C:\Users\Pisho\AppData\Local\Programs\Python\Python37\lib\site-packages\rest_framework\fields.py", line 454, in get_attribute
    return get_attribute(instance, self.source_attrs)
  File "C:\Users\Pisho\AppData\Local\Programs\Python\Python37\lib\site-packages\rest_framework\fields.py", line 94, in get_attribute
    instance = getattr(instance, attr)
AttributeError: 'User' object has no attribute 'userid'

During handling of the above exception, another exception occurred:

Traceback (most recent call last):
  File "C:\Users\Pisho\AppData\Roaming\Python\Python37\site-packages\django\core\handlers\exception.py", line 34, in inner
    response = get_response(request)
  File "C:\Users\Pisho\AppData\Roaming\Python\Python37\site-packages\django\core\handlers\base.py", line 115, in _get_response
    response = self.process_exception_by_middleware(e, request)
  File "C:\Users\Pisho\AppData\Roaming\Python\Python37\site-packages\django\core\handlers\base.py", line 113, in _get_response
    response = wrapped_callback(request, *callback_args, **callback_kwargs)
  File "C:\Users\Pisho\AppData\Roaming\Python\Python37\site-packages\django\views\decorators\csrf.py", line 54, in wrapped_view
    return view_func(*args, **kwargs)
  File "C:\Users\Pisho\AppData\Local\Programs\Python\Python37\lib\site-packages\rest_framework\viewsets.py", line 114, in view
    return self.dispatch(request, *args, **kwargs)
  File "C:\Users\Pisho\AppData\Local\Programs\Python\Python37\lib\site-packages\rest_framework\views.py", line 505, in dispatch
    response = self.handle_exception(exc)
  File "C:\Users\Pisho\AppData\Local\Programs\Python\Python37\lib\site-packages\rest_framework\views.py", line 465, in handle_exception
    self.raise_uncaught_exception(exc)
  File "C:\Users\Pisho\AppData\Local\Programs\Python\Python37\lib\site-packages\rest_framework\views.py", line 476, in raise_uncaught_exception
    raise exc
  File "C:\Users\Pisho\AppData\Local\Programs\Python\Python37\lib\site-packages\rest_framework\views.py", line 502, in dispatch
    response = handler(request, *args, **kwargs)
  File "C:\Users\Pisho\AppData\Local\Programs\Python\Python37\lib\site-packages\rest_framework\mixins.py", line 43, in list
    return self.get_paginated_response(serializer.data)
  File "C:\Users\Pisho\AppData\Local\Programs\Python\Python37\lib\site-packages\rest_framework\serializers.py", line 760, in data
    ret = super().data
  File "C:\Users\Pisho\AppData\Local\Programs\Python\Python37\lib\site-packages\rest_framework\serializers.py", line 260, in data
    self._data = self.to_representation(self.instance)
  File "C:\Users\Pisho\AppData\Local\Programs\Python\Python37\lib\site-packages\rest_framework\serializers.py", line 678, in to_representation
    self.child.to_representation(item) for item in iterable
  File "C:\Users\Pisho\AppData\Local\Programs\Python\Python37\lib\site-packages\rest_framework\serializers.py", line 678, in <listcomp>
    self.child.to_representation(item) for item in iterable
  File "C:\Users\Pisho\AppData\Local\Programs\Python\Python37\lib\site-packages\rest_framework\serializers.py", line 516, in to_representation
    attribute = field.get_attribute(instance)
  File "C:\Users\Pisho\AppData\Local\Programs\Python\Python37\lib\site-packages\rest_framework\fields.py", line 487, in get_attribute
    raise type(exc)(msg)
AttributeError: Got AttributeError when attempting to get a value for field `userid` on serializer `UserSerializer`.
The serializer field might be named incorrectly and not match any attribute or key on the `User` instance.
Original exception text was: 'User' object has no attribute 'userid'.
2019-43-27 11:43:51-log_response-ERROR-Internal Server Error: /apis/users/
Traceback (most recent call last):
  File "C:\Users\Pisho\AppData\Local\Programs\Python\Python37\lib\site-packages\rest_framework\fields.py", line 454, in get_attribute
    return get_attribute(instance, self.source_attrs)
  File "C:\Users\Pisho\AppData\Local\Programs\Python\Python37\lib\site-packages\rest_framework\fields.py", line 94, in get_attribute
    instance = getattr(instance, attr)
AttributeError: 'User' object has no attribute 'userid'

During handling of the above exception, another exception occurred:

Traceback (most recent call last):
  File "C:\Users\Pisho\AppData\Roaming\Python\Python37\site-packages\django\core\handlers\exception.py", line 34, in inner
    response = get_response(request)
  File "C:\Users\Pisho\AppData\Roaming\Python\Python37\site-packages\django\core\handlers\base.py", line 115, in _get_response
    response = self.process_exception_by_middleware(e, request)
  File "C:\Users\Pisho\AppData\Roaming\Python\Python37\site-packages\django\core\handlers\base.py", line 113, in _get_response
    response = wrapped_callback(request, *callback_args, **callback_kwargs)
  File "C:\Users\Pisho\AppData\Roaming\Python\Python37\site-packages\django\views\decorators\csrf.py", line 54, in wrapped_view
    return view_func(*args, **kwargs)
  File "C:\Users\Pisho\AppData\Local\Programs\Python\Python37\lib\site-packages\rest_framework\viewsets.py", line 114, in view
    return self.dispatch(request, *args, **kwargs)
  File "C:\Users\Pisho\AppData\Local\Programs\Python\Python37\lib\site-packages\rest_framework\views.py", line 505, in dispatch
    response = self.handle_exception(exc)
  File "C:\Users\Pisho\AppData\Local\Programs\Python\Python37\lib\site-packages\rest_framework\views.py", line 465, in handle_exception
    self.raise_uncaught_exception(exc)
  File "C:\Users\Pisho\AppData\Local\Programs\Python\Python37\lib\site-packages\rest_framework\views.py", line 476, in raise_uncaught_exception
    raise exc
  File "C:\Users\Pisho\AppData\Local\Programs\Python\Python37\lib\site-packages\rest_framework\views.py", line 502, in dispatch
    response = handler(request, *args, **kwargs)
  File "C:\Users\Pisho\AppData\Local\Programs\Python\Python37\lib\site-packages\rest_framework\mixins.py", line 43, in list
    return self.get_paginated_response(serializer.data)
  File "C:\Users\Pisho\AppData\Local\Programs\Python\Python37\lib\site-packages\rest_framework\serializers.py", line 760, in data
    ret = super().data
  File "C:\Users\Pisho\AppData\Local\Programs\Python\Python37\lib\site-packages\rest_framework\serializers.py", line 260, in data
    self._data = self.to_representation(self.instance)
  File "C:\Users\Pisho\AppData\Local\Programs\Python\Python37\lib\site-packages\rest_framework\serializers.py", line 678, in to_representation
    self.child.to_representation(item) for item in iterable
  File "C:\Users\Pisho\AppData\Local\Programs\Python\Python37\lib\site-packages\rest_framework\serializers.py", line 678, in <listcomp>
    self.child.to_representation(item) for item in iterable
  File "C:\Users\Pisho\AppData\Local\Programs\Python\Python37\lib\site-packages\rest_framework\serializers.py", line 516, in to_representation
    attribute = field.get_attribute(instance)
  File "C:\Users\Pisho\AppData\Local\Programs\Python\Python37\lib\site-packages\rest_framework\fields.py", line 487, in get_attribute
    raise type(exc)(msg)
AttributeError: Got AttributeError when attempting to get a value for field `userid` on serializer `UserSerializer`.
The serializer field might be named incorrectly and not match any attribute or key on the `User` instance.
Original exception text was: 'User' object has no attribute 'userid'.
2019-44-27 11:44:22-trigger_reload-INFO-D:\Study\School\e2e\app\djangoapp\backend\views.py changed, reloading.
2019-44-27 11:44:22-__init__-DEBUG-Using selector: SelectSelector
2019-44-27 11:44:28-trigger_reload-INFO-D:\Study\School\e2e\app\djangoapp\backend\views.py changed, reloading.
2019-44-27 11:44:28-__init__-DEBUG-Using selector: SelectSelector
2019-44-27 11:44:30-log_response-ERROR-Internal Server Error: /apis/users/
Traceback (most recent call last):
  File "C:\Users\Pisho\AppData\Roaming\Python\Python37\site-packages\django\core\handlers\exception.py", line 34, in inner
    response = get_response(request)
  File "C:\Users\Pisho\AppData\Roaming\Python\Python37\site-packages\django\core\handlers\base.py", line 115, in _get_response
    response = self.process_exception_by_middleware(e, request)
  File "C:\Users\Pisho\AppData\Roaming\Python\Python37\site-packages\django\core\handlers\base.py", line 113, in _get_response
    response = wrapped_callback(request, *callback_args, **callback_kwargs)
  File "C:\Users\Pisho\AppData\Roaming\Python\Python37\site-packages\django\views\decorators\csrf.py", line 54, in wrapped_view
    return view_func(*args, **kwargs)
  File "C:\Users\Pisho\AppData\Local\Programs\Python\Python37\lib\site-packages\rest_framework\viewsets.py", line 114, in view
    return self.dispatch(request, *args, **kwargs)
  File "C:\Users\Pisho\AppData\Local\Programs\Python\Python37\lib\site-packages\rest_framework\views.py", line 505, in dispatch
    response = self.handle_exception(exc)
  File "C:\Users\Pisho\AppData\Local\Programs\Python\Python37\lib\site-packages\rest_framework\views.py", line 465, in handle_exception
    self.raise_uncaught_exception(exc)
  File "C:\Users\Pisho\AppData\Local\Programs\Python\Python37\lib\site-packages\rest_framework\views.py", line 476, in raise_uncaught_exception
    raise exc
  File "C:\Users\Pisho\AppData\Local\Programs\Python\Python37\lib\site-packages\rest_framework\views.py", line 502, in dispatch
    response = handler(request, *args, **kwargs)
  File "C:\Users\Pisho\AppData\Local\Programs\Python\Python37\lib\site-packages\rest_framework\mixins.py", line 40, in list
    page = self.paginate_queryset(queryset)
  File "C:\Users\Pisho\AppData\Local\Programs\Python\Python37\lib\site-packages\rest_framework\generics.py", line 171, in paginate_queryset
    return self.paginator.paginate_queryset(queryset, self.request, view=self)
  File "C:\Users\Pisho\AppData\Local\Programs\Python\Python37\lib\site-packages\rest_framework\pagination.py", line 218, in paginate_queryset
    return list(self.page)
  File "C:\Users\Pisho\AppData\Roaming\Python\Python37\site-packages\django\core\paginator.py", line 150, in __len__
    return len(self.object_list)
  File "C:\Users\Pisho\AppData\Roaming\Python\Python37\site-packages\django\db\models\query.py", line 258, in __len__
    self._fetch_all()
  File "C:\Users\Pisho\AppData\Roaming\Python\Python37\site-packages\django\db\models\query.py", line 1261, in _fetch_all
    self._result_cache = list(self._iterable_class(self))
  File "C:\Users\Pisho\AppData\Roaming\Python\Python37\site-packages\django\db\models\query.py", line 57, in __iter__
    results = compiler.execute_sql(chunked_fetch=self.chunked_fetch, chunk_size=self.chunk_size)
  File "C:\Users\Pisho\AppData\Roaming\Python\Python37\site-packages\django\db\models\sql\compiler.py", line 1124, in execute_sql
    sql, params = self.as_sql()
  File "C:\Users\Pisho\AppData\Roaming\Python\Python37\site-packages\django\db\models\sql\compiler.py", line 483, in as_sql
    extra_select, order_by, group_by = self.pre_sql_setup()
  File "C:\Users\Pisho\AppData\Roaming\Python\Python37\site-packages\django\db\models\sql\compiler.py", line 52, in pre_sql_setup
    order_by = self.get_order_by()
  File "C:\Users\Pisho\AppData\Roaming\Python\Python37\site-packages\django\db\models\sql\compiler.py", line 335, in get_order_by
    field, self.query.get_meta(), default_order=asc))
  File "C:\Users\Pisho\AppData\Roaming\Python\Python37\site-packages\django\db\models\sql\compiler.py", line 713, in find_ordering_name
    field, targets, alias, joins, path, opts, transform_function = self._setup_joins(pieces, opts, alias)
  File "C:\Users\Pisho\AppData\Roaming\Python\Python37\site-packages\django\db\models\sql\compiler.py", line 748, in _setup_joins
    field, targets, opts, joins, path, transform_function = self.query.setup_joins(pieces, opts, alias)
  File "C:\Users\Pisho\AppData\Roaming\Python\Python37\site-packages\django\db\models\sql\query.py", line 1551, in setup_joins
    names[:pivot], opts, allow_many, fail_on_missing=True,
  File "C:\Users\Pisho\AppData\Roaming\Python\Python37\site-packages\django\db\models\sql\query.py", line 1467, in names_to_path
    "Choices are: %s" % (name, ", ".join(available)))
django.core.exceptions.FieldError: Cannot resolve keyword 'date_joined' into field. Choices are: ElephantPri, ElephantPub, IdentityPri, IdentityPub, OneTimePri, OneTimePub, SignedPri, SignedPub, userid
2019-44-27 11:44:38-trigger_reload-INFO-D:\Study\School\e2e\app\djangoapp\backend\views.py changed, reloading.
2019-44-27 11:44:38-__init__-DEBUG-Using selector: SelectSelector
2019-44-27 11:44:41-trigger_reload-INFO-D:\Study\School\e2e\app\djangoapp\backend\views.py changed, reloading.
2019-44-27 11:44:41-__init__-DEBUG-Using selector: SelectSelector
2019-44-27 11:44:58-__init__-DEBUG-Using selector: SelectSelector
2019-46-27 11:46:38-log_response-WARNING-Not Found: /apis/users/123/
2019-47-27 11:47:51-trigger_reload-INFO-D:\Study\School\e2e\app\djangoapp\backend\views.py changed, reloading.
2019-47-27 11:47:51-__init__-DEBUG-Using selector: SelectSelector
2019-47-27 11:47:55-trigger_reload-INFO-D:\Study\School\e2e\app\djangoapp\backend\views.py changed, reloading.
2019-47-27 11:47:55-__init__-DEBUG-Using selector: SelectSelector
2019-48-27 11:48:13-trigger_reload-INFO-D:\Study\School\e2e\app\djangoapp\backend\views.py changed, reloading.
2019-48-27 11:48:13-__init__-DEBUG-Using selector: SelectSelector
2019-48-27 11:48:36-get_live-INFO-127.0.0.1
2019-48-27 11:48:36-log_response-ERROR-Internal Server Error: /apis/get_live
Traceback (most recent call last):
  File "C:\Users\Pisho\AppData\Roaming\Python\Python37\site-packages\django\core\handlers\exception.py", line 34, in inner
    response = get_response(request)
  File "C:\Users\Pisho\AppData\Roaming\Python\Python37\site-packages\django\core\handlers\base.py", line 115, in _get_response
    response = self.process_exception_by_middleware(e, request)
  File "C:\Users\Pisho\AppData\Roaming\Python\Python37\site-packages\django\core\handlers\base.py", line 113, in _get_response
    response = wrapped_callback(request, *callback_args, **callback_kwargs)
  File "D:\Study\School\e2e\app\djangoapp\backend\views.py", line 53, in get_live
    return JsonResponse(json.dumps(result))
  File "C:\Users\Pisho\AppData\Roaming\Python\Python37\site-packages\django\http\response.py", line 581, in __init__
    'In order to allow non-dict objects to be serialized set the '
TypeError: In order to allow non-dict objects to be serialized set the safe parameter to False.
2019-49-27 11:49:03-trigger_reload-INFO-D:\Study\School\e2e\app\djangoapp\backend\views.py changed, reloading.
2019-49-27 11:49:03-__init__-DEBUG-Using selector: SelectSelector
2019-49-27 11:49:05-trigger_reload-INFO-D:\Study\School\e2e\app\djangoapp\backend\views.py changed, reloading.
2019-49-27 11:49:05-__init__-DEBUG-Using selector: SelectSelector
2019-49-27 11:49:08-trigger_reload-INFO-D:\Study\School\e2e\app\djangoapp\backend\views.py changed, reloading.
2019-49-27 11:49:08-__init__-DEBUG-Using selector: SelectSelector
2019-49-27 11:49:10-get_live-INFO-127.0.0.1
2019-49-27 11:49:27-trigger_reload-INFO-D:\Study\School\e2e\app\djangoapp\backend\views.py changed, reloading.
2019-49-27 11:49:27-__init__-DEBUG-Using selector: SelectSelector
2019-49-27 11:49:39-trigger_reload-INFO-D:\Study\School\e2e\app\djangoapp\backend\views.py changed, reloading.
2019-49-27 11:49:39-__init__-DEBUG-Using selector: SelectSelector
2019-49-27 11:49:41-trigger_reload-INFO-D:\Study\School\e2e\app\djangoapp\backend\views.py changed, reloading.
2019-49-27 11:49:41-__init__-DEBUG-Using selector: SelectSelector
2019-49-27 11:49:55-trigger_reload-INFO-D:\Study\School\e2e\app\djangoapp\backend\views.py changed, reloading.
2019-49-27 11:49:55-__init__-DEBUG-Using selector: SelectSelector
2019-50-27 11:50:22-trigger_reload-INFO-D:\Study\School\e2e\app\djangoapp\backend\models.py changed, reloading.
2019-50-27 11:50:22-__init__-DEBUG-Using selector: SelectSelector
2019-50-27 11:50:29-trigger_reload-INFO-D:\Study\School\e2e\app\djangoapp\backend\models.py changed, reloading.
2019-50-27 11:50:29-__init__-DEBUG-Using selector: SelectSelector
2019-50-27 11:50:43-trigger_reload-INFO-D:\Study\School\e2e\app\djangoapp\backend\models.py changed, reloading.
2019-50-27 11:50:43-__init__-DEBUG-Using selector: SelectSelector
2019-50-27 11:50:48-trigger_reload-INFO-D:\Study\School\e2e\app\djangoapp\backend\models.py changed, reloading.
2019-50-27 11:50:48-__init__-DEBUG-Using selector: SelectSelector
2019-51-27 11:51:04-trigger_reload-INFO-D:\Study\School\e2e\app\djangoapp\backend\serializers.py changed, reloading.
2019-51-27 11:51:04-__init__-DEBUG-Using selector: SelectSelector
2019-51-27 11:51:18-log_response-ERROR-Internal Server Error: /apis/users/
Traceback (most recent call last):
  File "C:\Users\Pisho\AppData\Roaming\Python\Python37\site-packages\django\core\handlers\exception.py", line 34, in inner
    response = get_response(request)
  File "C:\Users\Pisho\AppData\Roaming\Python\Python37\site-packages\django\core\handlers\base.py", line 145, in _get_response
    response = self.process_exception_by_middleware(e, request)
  File "C:\Users\Pisho\AppData\Roaming\Python\Python37\site-packages\django\core\handlers\base.py", line 143, in _get_response
    response = response.render()
  File "C:\Users\Pisho\AppData\Roaming\Python\Python37\site-packages\django\template\response.py", line 105, in render
    self.content = self.rendered_content
  File "C:\Users\Pisho\AppData\Local\Programs\Python\Python37\lib\site-packages\rest_framework\response.py", line 70, in rendered_content
    ret = renderer.render(self.data, accepted_media_type, context)
  File "C:\Users\Pisho\AppData\Local\Programs\Python\Python37\lib\site-packages\rest_framework\renderers.py", line 724, in render
    context = self.get_context(data, accepted_media_type, renderer_context)
  File "C:\Users\Pisho\AppData\Local\Programs\Python\Python37\lib\site-packages\rest_framework\renderers.py", line 655, in get_context
    raw_data_post_form = self.get_raw_data_form(data, view, 'POST', request)
  File "C:\Users\Pisho\AppData\Local\Programs\Python\Python37\lib\site-packages\rest_framework\renderers.py", line 563, in get_raw_data_form
    data = serializer.data.copy()
  File "C:\Users\Pisho\AppData\Local\Programs\Python\Python37\lib\site-packages\rest_framework\serializers.py", line 562, in data
    ret = super().data
  File "C:\Users\Pisho\AppData\Local\Programs\Python\Python37\lib\site-packages\rest_framework\serializers.py", line 264, in data
    self._data = self.get_initial()
  File "C:\Users\Pisho\AppData\Local\Programs\Python\Python37\lib\site-packages\rest_framework\serializers.py", line 412, in get_initial
    for field in self.fields.values()
  File "C:\Users\Pisho\AppData\Roaming\Python\Python37\site-packages\django\utils\functional.py", line 48, in __get__
    res = instance.__dict__[self.name] = self.func(instance)
  File "C:\Users\Pisho\AppData\Local\Programs\Python\Python37\lib\site-packages\rest_framework\serializers.py", line 363, in fields
    for key, value in self.get_fields().items():
  File "C:\Users\Pisho\AppData\Local\Programs\Python\Python37\lib\site-packages\rest_framework\serializers.py", line 1063, in get_fields
    source, info, model, depth
  File "C:\Users\Pisho\AppData\Local\Programs\Python\Python37\lib\site-packages\rest_framework\serializers.py", line 1208, in build_field
    return self.build_unknown_field(field_name, model_class)
  File "C:\Users\Pisho\AppData\Local\Programs\Python\Python37\lib\site-packages\rest_framework\serializers.py", line 1325, in build_unknown_field
    (field_name, model_class.__name__)
django.core.exceptions.ImproperlyConfigured: Field name `last_prot` is not valid for model `user`.
2019-51-27 11:51:32-trigger_reload-INFO-D:\Study\School\e2e\app\djangoapp\backend\serializers.py changed, reloading.
2019-51-27 11:51:32-__init__-DEBUG-Using selector: SelectSelector
2019-51-27 11:51:56-log_response-ERROR-Internal Server Error: /apis/users/
Traceback (most recent call last):
  File "C:\Users\Pisho\AppData\Roaming\Python\Python37\site-packages\django\db\backends\utils.py", line 86, in _execute
    return self.cursor.execute(sql, params)
  File "C:\Users\Pisho\AppData\Roaming\Python\Python37\site-packages\django\db\backends\sqlite3\base.py", line 396, in execute
    return Database.Cursor.execute(self, query, params)
sqlite3.OperationalError: table backend_user has no column named last_ip

The above exception was the direct cause of the following exception:

Traceback (most recent call last):
  File "C:\Users\Pisho\AppData\Roaming\Python\Python37\site-packages\django\core\handlers\exception.py", line 34, in inner
    response = get_response(request)
  File "C:\Users\Pisho\AppData\Roaming\Python\Python37\site-packages\django\core\handlers\base.py", line 115, in _get_response
    response = self.process_exception_by_middleware(e, request)
  File "C:\Users\Pisho\AppData\Roaming\Python\Python37\site-packages\django\core\handlers\base.py", line 113, in _get_response
    response = wrapped_callback(request, *callback_args, **callback_kwargs)
  File "C:\Users\Pisho\AppData\Roaming\Python\Python37\site-packages\django\views\decorators\csrf.py", line 54, in wrapped_view
    return view_func(*args, **kwargs)
  File "C:\Users\Pisho\AppData\Local\Programs\Python\Python37\lib\site-packages\rest_framework\viewsets.py", line 114, in view
    return self.dispatch(request, *args, **kwargs)
  File "C:\Users\Pisho\AppData\Local\Programs\Python\Python37\lib\site-packages\rest_framework\views.py", line 505, in dispatch
    response = self.handle_exception(exc)
  File "C:\Users\Pisho\AppData\Local\Programs\Python\Python37\lib\site-packages\rest_framework\views.py", line 465, in handle_exception
    self.raise_uncaught_exception(exc)
  File "C:\Users\Pisho\AppData\Local\Programs\Python\Python37\lib\site-packages\rest_framework\views.py", line 476, in raise_uncaught_exception
    raise exc
  File "C:\Users\Pisho\AppData\Local\Programs\Python\Python37\lib\site-packages\rest_framework\views.py", line 502, in dispatch
    response = handler(request, *args, **kwargs)
  File "C:\Users\Pisho\AppData\Local\Programs\Python\Python37\lib\site-packages\rest_framework\mixins.py", line 19, in create
    self.perform_create(serializer)
  File "C:\Users\Pisho\AppData\Local\Programs\Python\Python37\lib\site-packages\rest_framework\mixins.py", line 24, in perform_create
    serializer.save()
  File "C:\Users\Pisho\AppData\Local\Programs\Python\Python37\lib\site-packages\rest_framework\serializers.py", line 212, in save
    self.instance = self.create(validated_data)
  File "C:\Users\Pisho\AppData\Local\Programs\Python\Python37\lib\site-packages\rest_framework\serializers.py", line 948, in create
    instance = ModelClass._default_manager.create(**validated_data)
  File "C:\Users\Pisho\AppData\Roaming\Python\Python37\site-packages\django\db\models\manager.py", line 82, in manager_method
    return getattr(self.get_queryset(), name)(*args, **kwargs)
  File "C:\Users\Pisho\AppData\Roaming\Python\Python37\site-packages\django\db\models\query.py", line 433, in create
    obj.save(force_insert=True, using=self.db)
  File "C:\Users\Pisho\AppData\Roaming\Python\Python37\site-packages\django\db\models\base.py", line 746, in save
    force_update=force_update, update_fields=update_fields)
  File "C:\Users\Pisho\AppData\Roaming\Python\Python37\site-packages\django\db\models\base.py", line 784, in save_base
    force_update, using, update_fields,
  File "C:\Users\Pisho\AppData\Roaming\Python\Python37\site-packages\django\db\models\base.py", line 886, in _save_table
    results = self._do_insert(cls._base_manager, using, fields, returning_fields, raw)
  File "C:\Users\Pisho\AppData\Roaming\Python\Python37\site-packages\django\db\models\base.py", line 925, in _do_insert
    using=using, raw=raw,
  File "C:\Users\Pisho\AppData\Roaming\Python\Python37\site-packages\django\db\models\manager.py", line 82, in manager_method
    return getattr(self.get_queryset(), name)(*args, **kwargs)
  File "C:\Users\Pisho\AppData\Roaming\Python\Python37\site-packages\django\db\models\query.py", line 1204, in _insert
    return query.get_compiler(using=using).execute_sql(returning_fields)
  File "C:\Users\Pisho\AppData\Roaming\Python\Python37\site-packages\django\db\models\sql\compiler.py", line 1377, in execute_sql
    cursor.execute(sql, params)
  File "C:\Users\Pisho\AppData\Roaming\Python\Python37\site-packages\django\db\backends\utils.py", line 100, in execute
    return super().execute(sql, params)
  File "C:\Users\Pisho\AppData\Roaming\Python\Python37\site-packages\django\db\backends\utils.py", line 68, in execute
    return self._execute_with_wrappers(sql, params, many=False, executor=self._execute)
  File "C:\Users\Pisho\AppData\Roaming\Python\Python37\site-packages\django\db\backends\utils.py", line 77, in _execute_with_wrappers
    return executor(sql, params, many, context)
  File "C:\Users\Pisho\AppData\Roaming\Python\Python37\site-packages\django\db\backends\utils.py", line 86, in _execute
    return self.cursor.execute(sql, params)
  File "C:\Users\Pisho\AppData\Roaming\Python\Python37\site-packages\django\db\utils.py", line 90, in __exit__
    raise dj_exc_value.with_traceback(traceback) from exc_value
  File "C:\Users\Pisho\AppData\Roaming\Python\Python37\site-packages\django\db\backends\utils.py", line 86, in _execute
    return self.cursor.execute(sql, params)
  File "C:\Users\Pisho\AppData\Roaming\Python\Python37\site-packages\django\db\backends\sqlite3\base.py", line 396, in execute
    return Database.Cursor.execute(self, query, params)
django.db.utils.OperationalError: table backend_user has no column named last_ip
2019-52-27 11:52:06-__init__-DEBUG-Using selector: SelectSelector
2019-52-27 11:52:29-__init__-DEBUG-Using selector: SelectSelector
2019-52-27 11:52:57-__init__-DEBUG-Using selector: SelectSelector
2019-53-27 11:53:05-__init__-DEBUG-Using selector: SelectSelector
2019-53-27 11:53:18-log_response-WARNING-Bad Request: /apis/users/
2019-54-27 11:54:40-trigger_reload-INFO-D:\Study\School\e2e\app\djangoapp\backend\views.py changed, reloading.
2019-54-27 11:54:40-__init__-DEBUG-Using selector: SelectSelector
2019-55-27 11:55:04-trigger_reload-INFO-D:\Study\School\e2e\app\djangoapp\backend\views.py changed, reloading.
2019-55-27 11:55:04-__init__-DEBUG-Using selector: SelectSelector
2019-55-27 11:55:17-trigger_reload-INFO-D:\Study\School\e2e\app\djangoapp\backend\views.py changed, reloading.
2019-55-27 11:55:17-__init__-DEBUG-Using selector: SelectSelector
2019-55-27 11:55:30-trigger_reload-INFO-D:\Study\School\e2e\app\djangoapp\backend\views.py changed, reloading.
2019-55-27 11:55:30-__init__-DEBUG-Using selector: SelectSelector
2019-56-27 11:56:52-__init__-DEBUG-Using selector: SelectSelector
2019-57-27 11:57:34-log_response-WARNING-Not Found: /apis/user/
2019-57-27 11:57:37-log_response-ERROR-Internal Server Error: /apis/user
Traceback (most recent call last):
  File "C:\Users\Pisho\AppData\Roaming\Python\Python37\site-packages\django\core\handlers\exception.py", line 34, in inner
    response = get_response(request)
  File "C:\Users\Pisho\AppData\Roaming\Python\Python37\site-packages\django\core\handlers\base.py", line 115, in _get_response
    response = self.process_exception_by_middleware(e, request)
  File "C:\Users\Pisho\AppData\Roaming\Python\Python37\site-packages\django\core\handlers\base.py", line 113, in _get_response
    response = wrapped_callback(request, *callback_args, **callback_kwargs)
  File "C:\Users\Pisho\AppData\Roaming\Python\Python37\site-packages\django\views\decorators\csrf.py", line 54, in wrapped_view
    return view_func(*args, **kwargs)
  File "C:\Users\Pisho\AppData\Roaming\Python\Python37\site-packages\django\views\generic\base.py", line 71, in view
    return self.dispatch(request, *args, **kwargs)
  File "C:\Users\Pisho\AppData\Local\Programs\Python\Python37\lib\site-packages\rest_framework\views.py", line 507, in dispatch
    self.response = self.finalize_response(request, response, *args, **kwargs)
  File "C:\Users\Pisho\AppData\Local\Programs\Python\Python37\lib\site-packages\rest_framework\views.py", line 422, in finalize_response
    % type(response)
AssertionError: Expected a `Response`, `HttpResponse` or `HttpStreamingResponse` to be returned from the view, but received a `<class 'NoneType'>`
2019-58-27 11:58:00-trigger_reload-INFO-D:\Study\School\e2e\app\djangoapp\backend\views.py changed, reloading.
2019-58-27 11:58:00-__init__-DEBUG-Using selector: SelectSelector
2019-58-27 11:58:03-trigger_reload-INFO-D:\Study\School\e2e\app\djangoapp\backend\views.py changed, reloading.
2019-58-27 11:58:03-__init__-DEBUG-Using selector: SelectSelector
2019-58-27 11:58:13-trigger_reload-INFO-D:\Study\School\e2e\app\djangoapp\backend\views.py changed, reloading.
2019-58-27 11:58:13-__init__-DEBUG-Using selector: SelectSelector
2019-59-27 11:59:13-trigger_reload-INFO-D:\Study\School\e2e\app\djangoapp\backend\views.py changed, reloading.
2019-59-27 11:59:13-__init__-DEBUG-Using selector: SelectSelector
2019-59-27 11:59:16-log_response-ERROR-Internal Server Error: /apis/user
Traceback (most recent call last):
  File "C:\Users\Pisho\AppData\Roaming\Python\Python37\site-packages\django\core\handlers\exception.py", line 34, in inner
    response = get_response(request)
  File "C:\Users\Pisho\AppData\Roaming\Python\Python37\site-packages\django\core\handlers\base.py", line 115, in _get_response
    response = self.process_exception_by_middleware(e, request)
  File "C:\Users\Pisho\AppData\Roaming\Python\Python37\site-packages\django\core\handlers\base.py", line 113, in _get_response
    response = wrapped_callback(request, *callback_args, **callback_kwargs)
  File "C:\Users\Pisho\AppData\Roaming\Python\Python37\site-packages\django\views\decorators\csrf.py", line 54, in wrapped_view
    return view_func(*args, **kwargs)
  File "C:\Users\Pisho\AppData\Roaming\Python\Python37\site-packages\django\views\generic\base.py", line 71, in view
    return self.dispatch(request, *args, **kwargs)
  File "C:\Users\Pisho\AppData\Local\Programs\Python\Python37\lib\site-packages\rest_framework\views.py", line 505, in dispatch
    response = self.handle_exception(exc)
  File "C:\Users\Pisho\AppData\Local\Programs\Python\Python37\lib\site-packages\rest_framework\views.py", line 465, in handle_exception
    self.raise_uncaught_exception(exc)
  File "C:\Users\Pisho\AppData\Local\Programs\Python\Python37\lib\site-packages\rest_framework\views.py", line 476, in raise_uncaught_exception
    raise exc
  File "C:\Users\Pisho\AppData\Local\Programs\Python\Python37\lib\site-packages\rest_framework\views.py", line 502, in dispatch
    response = handler(request, *args, **kwargs)
  File "C:\Users\Pisho\AppData\Local\Programs\Python\Python37\lib\site-packages\rest_framework\decorators.py", line 50, in handler
    return func(*args, **kwargs)
  File "D:\Study\School\e2e\app\djangoapp\backend\views.py", line 168, in UserViewSet
    return JsonResponse(serializer.data)
  File "C:\Users\Pisho\AppData\Roaming\Python\Python37\site-packages\django\http\response.py", line 581, in __init__
    'In order to allow non-dict objects to be serialized set the '
TypeError: In order to allow non-dict objects to be serialized set the safe parameter to False.
2019-59-27 11:59:38-trigger_reload-INFO-D:\Study\School\e2e\app\djangoapp\backend\views.py changed, reloading.
2019-59-27 11:59:38-__init__-DEBUG-Using selector: SelectSelector
2019-59-27 11:59:44-trigger_reload-INFO-D:\Study\School\e2e\app\djangoapp\backend\views.py changed, reloading.
2019-59-27 11:59:44-__init__-DEBUG-Using selector: SelectSelector
2019-59-27 11:59:47-trigger_reload-INFO-D:\Study\School\e2e\app\djangoapp\backend\views.py changed, reloading.
2019-59-27 11:59:47-__init__-DEBUG-Using selector: SelectSelector
2019-00-27 12:00:23-log_response-WARNING-Not Found: /favicon.ico
2019-01-27 12:01:24-trigger_reload-INFO-D:\Study\School\e2e\app\djangoapp\backend\views.py changed, reloading.
2019-01-27 12:01:24-__init__-DEBUG-Using selector: SelectSelector
2019-01-27 12:01:26-trigger_reload-INFO-D:\Study\School\e2e\app\djangoapp\backend\views.py changed, reloading.
2019-01-27 12:01:26-__init__-DEBUG-Using selector: SelectSelector
2019-01-27 12:01:37-trigger_reload-INFO-D:\Study\School\e2e\app\djangoapp\backend\views.py changed, reloading.
2019-01-27 12:01:37-__init__-DEBUG-Using selector: SelectSelector
2019-01-27 12:01:39-trigger_reload-INFO-D:\Study\School\e2e\app\djangoapp\backend\views.py changed, reloading.
2019-01-27 12:01:39-__init__-DEBUG-Using selector: SelectSelector
2019-01-27 12:01:43-trigger_reload-INFO-D:\Study\School\e2e\app\djangoapp\backend\views.py changed, reloading.
2019-01-27 12:01:43-__init__-DEBUG-Using selector: SelectSelector
2019-01-27 12:01:51-trigger_reload-INFO-D:\Study\School\e2e\app\djangoapp\backend\views.py changed, reloading.
2019-01-27 12:01:51-__init__-DEBUG-Using selector: SelectSelector
2019-02-27 12:02:01-trigger_reload-INFO-D:\Study\School\e2e\app\djangoapp\backend\urls.py changed, reloading.
2019-02-27 12:02:01-__init__-DEBUG-Using selector: SelectSelector
2019-02-27 12:02:28-log_response-ERROR-Internal Server Error: /apis/user_detail
Traceback (most recent call last):
  File "C:\Users\Pisho\AppData\Roaming\Python\Python37\site-packages\django\core\handlers\exception.py", line 34, in inner
    response = get_response(request)
  File "C:\Users\Pisho\AppData\Roaming\Python\Python37\site-packages\django\core\handlers\base.py", line 115, in _get_response
    response = self.process_exception_by_middleware(e, request)
  File "C:\Users\Pisho\AppData\Roaming\Python\Python37\site-packages\django\core\handlers\base.py", line 113, in _get_response
    response = wrapped_callback(request, *callback_args, **callback_kwargs)
  File "C:\Users\Pisho\AppData\Roaming\Python\Python37\site-packages\django\views\decorators\csrf.py", line 54, in wrapped_view
    return view_func(*args, **kwargs)
  File "C:\Users\Pisho\AppData\Roaming\Python\Python37\site-packages\django\views\generic\base.py", line 71, in view
    return self.dispatch(request, *args, **kwargs)
  File "C:\Users\Pisho\AppData\Local\Programs\Python\Python37\lib\site-packages\rest_framework\views.py", line 505, in dispatch
    response = self.handle_exception(exc)
  File "C:\Users\Pisho\AppData\Local\Programs\Python\Python37\lib\site-packages\rest_framework\views.py", line 465, in handle_exception
    self.raise_uncaught_exception(exc)
  File "C:\Users\Pisho\AppData\Local\Programs\Python\Python37\lib\site-packages\rest_framework\views.py", line 476, in raise_uncaught_exception
    raise exc
  File "C:\Users\Pisho\AppData\Local\Programs\Python\Python37\lib\site-packages\rest_framework\views.py", line 502, in dispatch
    response = handler(request, *args, **kwargs)
  File "C:\Users\Pisho\AppData\Local\Programs\Python\Python37\lib\site-packages\rest_framework\decorators.py", line 50, in handler
    return func(*args, **kwargs)
TypeError: user_detail() missing 1 required positional argument: 'pk'
2019-02-27 12:02:49-trigger_reload-INFO-D:\Study\School\e2e\app\djangoapp\backend\views.py changed, reloading.
2019-02-27 12:02:49-__init__-DEBUG-Using selector: SelectSelector
2019-02-27 12:02:52-trigger_reload-INFO-D:\Study\School\e2e\app\djangoapp\backend\views.py changed, reloading.
2019-02-27 12:02:52-__init__-DEBUG-Using selector: SelectSelector
2019-02-27 12:02:57-trigger_reload-INFO-D:\Study\School\e2e\app\djangoapp\backend\urls.py changed, reloading.
2019-02-27 12:02:57-__init__-DEBUG-Using selector: SelectSelector
2019-03-27 12:03:09-trigger_reload-INFO-D:\Study\School\e2e\app\djangoapp\backend\urls.py changed, reloading.
2019-03-27 12:03:09-__init__-DEBUG-Using selector: SelectSelector
2019-03-27 12:03:36-__init__-DEBUG-Using selector: SelectSelector
2019-03-27 12:03:40-log_response-WARNING-Not Found: /apis/user_detail
2019-03-27 12:03:41-log_response-WARNING-Not Found: /apis/user_detail
2019-03-27 12:03:47-log_response-ERROR-Internal Server Error: /apis/user/6
Traceback (most recent call last):
  File "D:\Study\School\e2e\app\djangoapp\backend\views.py", line 186, in user_detail
    user = user.objects.get(pk=pk)
UnboundLocalError: local variable 'user' referenced before assignment

During handling of the above exception, another exception occurred:

Traceback (most recent call last):
  File "C:\Users\Pisho\AppData\Roaming\Python\Python37\site-packages\django\core\handlers\exception.py", line 34, in inner
    response = get_response(request)
  File "C:\Users\Pisho\AppData\Roaming\Python\Python37\site-packages\django\core\handlers\base.py", line 115, in _get_response
    response = self.process_exception_by_middleware(e, request)
  File "C:\Users\Pisho\AppData\Roaming\Python\Python37\site-packages\django\core\handlers\base.py", line 113, in _get_response
    response = wrapped_callback(request, *callback_args, **callback_kwargs)
  File "C:\Users\Pisho\AppData\Roaming\Python\Python37\site-packages\django\views\decorators\csrf.py", line 54, in wrapped_view
    return view_func(*args, **kwargs)
  File "C:\Users\Pisho\AppData\Roaming\Python\Python37\site-packages\django\views\generic\base.py", line 71, in view
    return self.dispatch(request, *args, **kwargs)
  File "C:\Users\Pisho\AppData\Local\Programs\Python\Python37\lib\site-packages\rest_framework\views.py", line 505, in dispatch
    response = self.handle_exception(exc)
  File "C:\Users\Pisho\AppData\Local\Programs\Python\Python37\lib\site-packages\rest_framework\views.py", line 465, in handle_exception
    self.raise_uncaught_exception(exc)
  File "C:\Users\Pisho\AppData\Local\Programs\Python\Python37\lib\site-packages\rest_framework\views.py", line 476, in raise_uncaught_exception
    raise exc
  File "C:\Users\Pisho\AppData\Local\Programs\Python\Python37\lib\site-packages\rest_framework\views.py", line 502, in dispatch
    response = handler(request, *args, **kwargs)
  File "C:\Users\Pisho\AppData\Local\Programs\Python\Python37\lib\site-packages\rest_framework\decorators.py", line 50, in handler
    return func(*args, **kwargs)
  File "D:\Study\School\e2e\app\djangoapp\backend\views.py", line 187, in user_detail
    except user.DoesNotExist:
UnboundLocalError: local variable 'user' referenced before assignment
2019-04-27 12:04:27-log_response-WARNING-Not Found: /apis/user/6/
2019-04-27 12:04:37-log_response-ERROR-Internal Server Error: /apis/user/6
Traceback (most recent call last):
  File "D:\Study\School\e2e\app\djangoapp\backend\views.py", line 186, in user_detail
    user = user.objects.get(pk=pk)
UnboundLocalError: local variable 'user' referenced before assignment

During handling of the above exception, another exception occurred:

Traceback (most recent call last):
  File "C:\Users\Pisho\AppData\Roaming\Python\Python37\site-packages\django\core\handlers\exception.py", line 34, in inner
    response = get_response(request)
  File "C:\Users\Pisho\AppData\Roaming\Python\Python37\site-packages\django\core\handlers\base.py", line 115, in _get_response
    response = self.process_exception_by_middleware(e, request)
  File "C:\Users\Pisho\AppData\Roaming\Python\Python37\site-packages\django\core\handlers\base.py", line 113, in _get_response
    response = wrapped_callback(request, *callback_args, **callback_kwargs)
  File "C:\Users\Pisho\AppData\Roaming\Python\Python37\site-packages\django\views\decorators\csrf.py", line 54, in wrapped_view
    return view_func(*args, **kwargs)
  File "C:\Users\Pisho\AppData\Roaming\Python\Python37\site-packages\django\views\generic\base.py", line 71, in view
    return self.dispatch(request, *args, **kwargs)
  File "C:\Users\Pisho\AppData\Local\Programs\Python\Python37\lib\site-packages\rest_framework\views.py", line 505, in dispatch
    response = self.handle_exception(exc)
  File "C:\Users\Pisho\AppData\Local\Programs\Python\Python37\lib\site-packages\rest_framework\views.py", line 465, in handle_exception
    self.raise_uncaught_exception(exc)
  File "C:\Users\Pisho\AppData\Local\Programs\Python\Python37\lib\site-packages\rest_framework\views.py", line 476, in raise_uncaught_exception
    raise exc
  File "C:\Users\Pisho\AppData\Local\Programs\Python\Python37\lib\site-packages\rest_framework\views.py", line 502, in dispatch
    response = handler(request, *args, **kwargs)
  File "C:\Users\Pisho\AppData\Local\Programs\Python\Python37\lib\site-packages\rest_framework\decorators.py", line 50, in handler
    return func(*args, **kwargs)
  File "D:\Study\School\e2e\app\djangoapp\backend\views.py", line 187, in user_detail
    except user.DoesNotExist:
UnboundLocalError: local variable 'user' referenced before assignment
2019-04-27 12:04:51-trigger_reload-INFO-D:\Study\School\e2e\app\djangoapp\backend\views.py changed, reloading.
2019-04-27 12:04:51-__init__-DEBUG-Using selector: SelectSelector
2019-04-27 12:04:54-trigger_reload-INFO-D:\Study\School\e2e\app\djangoapp\backend\views.py changed, reloading.
2019-04-27 12:04:54-__init__-DEBUG-Using selector: SelectSelector
2019-04-27 12:04:55-log_response-ERROR-Internal Server Error: /apis/user/6
Traceback (most recent call last):
  File "D:\Study\School\e2e\app\djangoapp\backend\views.py", line 186, in user_detail
    user = user.objects.get(userid=pk)
UnboundLocalError: local variable 'user' referenced before assignment

During handling of the above exception, another exception occurred:

Traceback (most recent call last):
  File "C:\Users\Pisho\AppData\Roaming\Python\Python37\site-packages\django\core\handlers\exception.py", line 34, in inner
    response = get_response(request)
  File "C:\Users\Pisho\AppData\Roaming\Python\Python37\site-packages\django\core\handlers\base.py", line 115, in _get_response
    response = self.process_exception_by_middleware(e, request)
  File "C:\Users\Pisho\AppData\Roaming\Python\Python37\site-packages\django\core\handlers\base.py", line 113, in _get_response
    response = wrapped_callback(request, *callback_args, **callback_kwargs)
  File "C:\Users\Pisho\AppData\Roaming\Python\Python37\site-packages\django\views\decorators\csrf.py", line 54, in wrapped_view
    return view_func(*args, **kwargs)
  File "C:\Users\Pisho\AppData\Roaming\Python\Python37\site-packages\django\views\generic\base.py", line 71, in view
    return self.dispatch(request, *args, **kwargs)
  File "C:\Users\Pisho\AppData\Local\Programs\Python\Python37\lib\site-packages\rest_framework\views.py", line 505, in dispatch
    response = self.handle_exception(exc)
  File "C:\Users\Pisho\AppData\Local\Programs\Python\Python37\lib\site-packages\rest_framework\views.py", line 465, in handle_exception
    self.raise_uncaught_exception(exc)
  File "C:\Users\Pisho\AppData\Local\Programs\Python\Python37\lib\site-packages\rest_framework\views.py", line 476, in raise_uncaught_exception
    raise exc
  File "C:\Users\Pisho\AppData\Local\Programs\Python\Python37\lib\site-packages\rest_framework\views.py", line 502, in dispatch
    response = handler(request, *args, **kwargs)
  File "C:\Users\Pisho\AppData\Local\Programs\Python\Python37\lib\site-packages\rest_framework\decorators.py", line 50, in handler
    return func(*args, **kwargs)
  File "D:\Study\School\e2e\app\djangoapp\backend\views.py", line 187, in user_detail
    except user.DoesNotExist:
UnboundLocalError: local variable 'user' referenced before assignment
2019-05-27 12:05:05-trigger_reload-INFO-D:\Study\School\e2e\app\djangoapp\backend\views.py changed, reloading.
2019-05-27 12:05:05-__init__-DEBUG-Using selector: SelectSelector
2019-05-27 12:05:10-trigger_reload-INFO-D:\Study\School\e2e\app\djangoapp\backend\views.py changed, reloading.
2019-05-27 12:05:10-__init__-DEBUG-Using selector: SelectSelector
2019-05-27 12:05:25-trigger_reload-INFO-D:\Study\School\e2e\app\djangoapp\backend\views.py changed, reloading.
2019-05-27 12:05:25-__init__-DEBUG-Using selector: SelectSelector
2019-05-27 12:05:29-trigger_reload-INFO-D:\Study\School\e2e\app\djangoapp\backend\views.py changed, reloading.
2019-05-27 12:05:29-__init__-DEBUG-Using selector: SelectSelector
2019-05-27 12:05:32-trigger_reload-INFO-D:\Study\School\e2e\app\djangoapp\backend\views.py changed, reloading.
2019-05-27 12:05:32-__init__-DEBUG-Using selector: SelectSelector
2019-09-27 12:09:06-trigger_reload-INFO-D:\Study\School\e2e\app\djangoapp\backend\views.py changed, reloading.
2019-09-27 12:09:06-__init__-DEBUG-Using selector: SelectSelector
2019-09-27 12:09:21-trigger_reload-INFO-D:\Study\School\e2e\app\djangoapp\backend\views.py changed, reloading.
2019-09-27 12:09:21-__init__-DEBUG-Using selector: SelectSelector
2019-09-27 12:09:27-trigger_reload-INFO-D:\Study\School\e2e\app\djangoapp\backend\views.py changed, reloading.
2019-09-27 12:09:27-__init__-DEBUG-Using selector: SelectSelector
2019-09-27 12:09:30-trigger_reload-INFO-D:\Study\School\e2e\app\djangoapp\backend\views.py changed, reloading.
2019-09-27 12:09:30-__init__-DEBUG-Using selector: SelectSelector
2019-09-27 12:09:35-trigger_reload-INFO-D:\Study\School\e2e\app\djangoapp\backend\views.py changed, reloading.
2019-09-27 12:09:35-__init__-DEBUG-Using selector: SelectSelector
2019-09-27 12:09:39-trigger_reload-INFO-D:\Study\School\e2e\app\djangoapp\backend\views.py changed, reloading.
2019-09-27 12:09:39-__init__-DEBUG-Using selector: SelectSelector
2019-09-27 12:09:54-trigger_reload-INFO-D:\Study\School\e2e\app\djangoapp\backend\views.py changed, reloading.
2019-09-27 12:09:54-__init__-DEBUG-Using selector: SelectSelector
2019-10-27 12:10:00-trigger_reload-INFO-D:\Study\School\e2e\app\djangoapp\backend\views.py changed, reloading.
2019-10-27 12:10:00-__init__-DEBUG-Using selector: SelectSelector
2019-10-27 12:10:03-log_response-ERROR-Internal Server Error: /apis/user/6
Traceback (most recent call last):
  File "C:\Users\Pisho\AppData\Roaming\Python\Python37\site-packages\django\core\handlers\exception.py", line 34, in inner
    response = get_response(request)
  File "C:\Users\Pisho\AppData\Roaming\Python\Python37\site-packages\django\core\handlers\base.py", line 115, in _get_response
    response = self.process_exception_by_middleware(e, request)
  File "C:\Users\Pisho\AppData\Roaming\Python\Python37\site-packages\django\core\handlers\base.py", line 113, in _get_response
    response = wrapped_callback(request, *callback_args, **callback_kwargs)
TypeError: __init__() takes 1 positional argument but 2 were given
2019-10-27 12:10:44-log_response-ERROR-Internal Server Error: /apis/user/
Traceback (most recent call last):
  File "C:\Users\Pisho\AppData\Roaming\Python\Python37\site-packages\django\core\handlers\exception.py", line 34, in inner
    response = get_response(request)
  File "C:\Users\Pisho\AppData\Roaming\Python\Python37\site-packages\django\core\handlers\base.py", line 115, in _get_response
    response = self.process_exception_by_middleware(e, request)
  File "C:\Users\Pisho\AppData\Roaming\Python\Python37\site-packages\django\core\handlers\base.py", line 113, in _get_response
    response = wrapped_callback(request, *callback_args, **callback_kwargs)
TypeError: __init__() takes 1 positional argument but 2 were given
2019-12-27 12:12:19-log_response-ERROR-Internal Server Error: /apis/user/
Traceback (most recent call last):
  File "C:\Users\Pisho\AppData\Roaming\Python\Python37\site-packages\django\core\handlers\exception.py", line 34, in inner
    response = get_response(request)
  File "C:\Users\Pisho\AppData\Roaming\Python\Python37\site-packages\django\core\handlers\base.py", line 115, in _get_response
    response = self.process_exception_by_middleware(e, request)
  File "C:\Users\Pisho\AppData\Roaming\Python\Python37\site-packages\django\core\handlers\base.py", line 113, in _get_response
    response = wrapped_callback(request, *callback_args, **callback_kwargs)
TypeError: __init__() takes 1 positional argument but 2 were given
2019-13-27 12:13:43-log_response-ERROR-Internal Server Error: /apis/user/
Traceback (most recent call last):
  File "C:\Users\Pisho\AppData\Roaming\Python\Python37\site-packages\django\core\handlers\exception.py", line 34, in inner
    response = get_response(request)
  File "C:\Users\Pisho\AppData\Roaming\Python\Python37\site-packages\django\core\handlers\base.py", line 115, in _get_response
    response = self.process_exception_by_middleware(e, request)
  File "C:\Users\Pisho\AppData\Roaming\Python\Python37\site-packages\django\core\handlers\base.py", line 113, in _get_response
    response = wrapped_callback(request, *callback_args, **callback_kwargs)
TypeError: __init__() takes 1 positional argument but 2 were given
2019-14-27 12:14:05-trigger_reload-INFO-D:\Study\School\e2e\app\djangoapp\backend\views.py changed, reloading.
2019-14-27 12:14:06-__init__-DEBUG-Using selector: SelectSelector
2019-14-27 12:14:11-log_response-ERROR-Internal Server Error: /apis/user/
Traceback (most recent call last):
  File "C:\Users\Pisho\AppData\Roaming\Python\Python37\site-packages\django\core\handlers\exception.py", line 34, in inner
    response = get_response(request)
  File "C:\Users\Pisho\AppData\Roaming\Python\Python37\site-packages\django\core\handlers\base.py", line 115, in _get_response
    response = self.process_exception_by_middleware(e, request)
  File "C:\Users\Pisho\AppData\Roaming\Python\Python37\site-packages\django\core\handlers\base.py", line 113, in _get_response
    response = wrapped_callback(request, *callback_args, **callback_kwargs)
TypeError: __init__() takes 1 positional argument but 2 were given
2019-14-27 12:14:32-__init__-DEBUG-Using selector: SelectSelector
2019-15-27 12:15:31-trigger_reload-INFO-D:\Study\School\e2e\app\djangoapp\djangoapp\settings.py changed, reloading.
2019-15-27 12:15:31-__init__-DEBUG-Using selector: SelectSelector
2019-15-27 12:15:39-trigger_reload-INFO-D:\Study\School\e2e\app\djangoapp\djangoapp\settings.py changed, reloading.
2019-15-27 12:15:39-__init__-DEBUG-Using selector: SelectSelector
2019-15-27 12:15:42-trigger_reload-INFO-D:\Study\School\e2e\app\djangoapp\djangoapp\settings.py changed, reloading.
2019-15-27 12:15:42-__init__-DEBUG-Using selector: SelectSelector
2019-15-27 12:15:48-trigger_reload-INFO-D:\Study\School\e2e\app\djangoapp\djangoapp\settings.py changed, reloading.
2019-15-27 12:15:48-__init__-DEBUG-Using selector: SelectSelector
2019-15-27 12:15:52-log_response-ERROR-Internal Server Error: /apis/
Traceback (most recent call last):
  File "C:\Users\Pisho\AppData\Roaming\Python\Python37\site-packages\django\core\handlers\exception.py", line 34, in inner
    response = get_response(request)
  File "C:\Users\Pisho\AppData\Roaming\Python\Python37\site-packages\django\core\handlers\base.py", line 145, in _get_response
    response = self.process_exception_by_middleware(e, request)
  File "C:\Users\Pisho\AppData\Roaming\Python\Python37\site-packages\django\core\handlers\base.py", line 143, in _get_response
    response = response.render()
  File "C:\Users\Pisho\AppData\Roaming\Python\Python37\site-packages\django\template\response.py", line 105, in render
    self.content = self.rendered_content
  File "C:\Users\Pisho\AppData\Roaming\Python\Python37\site-packages\django\template\response.py", line 81, in rendered_content
    template = self.resolve_template(self.template_name)
  File "C:\Users\Pisho\AppData\Roaming\Python\Python37\site-packages\django\template\response.py", line 63, in resolve_template
    return select_template(template, using=self.using)
  File "C:\Users\Pisho\AppData\Roaming\Python\Python37\site-packages\django\template\loader.py", line 47, in select_template
    raise TemplateDoesNotExist(', '.join(template_name_list), chain=chain)
django.template.exceptions.TemplateDoesNotExist: index.html
2019-16-27 12:16:01-trigger_reload-INFO-D:\Study\School\e2e\app\djangoapp\djangoapp\settings.py changed, reloading.
2019-16-27 12:16:01-__init__-DEBUG-Using selector: SelectSelector
2019-16-27 12:16:10-log_response-ERROR-Internal Server Error: /apis/user/
Traceback (most recent call last):
  File "C:\Users\Pisho\AppData\Roaming\Python\Python37\site-packages\django\core\handlers\exception.py", line 34, in inner
    response = get_response(request)
  File "C:\Users\Pisho\AppData\Roaming\Python\Python37\site-packages\django\core\handlers\base.py", line 115, in _get_response
    response = self.process_exception_by_middleware(e, request)
  File "C:\Users\Pisho\AppData\Roaming\Python\Python37\site-packages\django\core\handlers\base.py", line 113, in _get_response
    response = wrapped_callback(request, *callback_args, **callback_kwargs)
TypeError: __init__() takes 1 positional argument but 2 were given
2019-16-27 12:16:58-trigger_reload-INFO-D:\Study\School\e2e\app\djangoapp\backend\views.py changed, reloading.
2019-16-27 12:16:58-__init__-DEBUG-Using selector: SelectSelector
2019-17-27 12:17:04-trigger_reload-INFO-D:\Study\School\e2e\app\djangoapp\backend\views.py changed, reloading.
2019-17-27 12:17:04-__init__-DEBUG-Using selector: SelectSelector
2019-17-27 12:17:24-trigger_reload-INFO-D:\Study\School\e2e\app\djangoapp\backend\views.py changed, reloading.
2019-17-27 12:17:24-__init__-DEBUG-Using selector: SelectSelector
2019-17-27 12:17:26-trigger_reload-INFO-D:\Study\School\e2e\app\djangoapp\backend\views.py changed, reloading.
2019-17-27 12:17:26-__init__-DEBUG-Using selector: SelectSelector
2019-17-27 12:17:39-trigger_reload-INFO-D:\Study\School\e2e\app\djangoapp\backend\views.py changed, reloading.
2019-17-27 12:17:39-__init__-DEBUG-Using selector: SelectSelector
2019-17-27 12:17:43-trigger_reload-INFO-D:\Study\School\e2e\app\djangoapp\backend\views.py changed, reloading.
2019-17-27 12:17:43-__init__-DEBUG-Using selector: SelectSelector
2019-17-27 12:17:50-trigger_reload-INFO-D:\Study\School\e2e\app\djangoapp\backend\views.py changed, reloading.
2019-17-27 12:17:50-__init__-DEBUG-Using selector: SelectSelector
2019-18-27 12:18:05-trigger_reload-INFO-D:\Study\School\e2e\app\djangoapp\backend\views.py changed, reloading.
2019-18-27 12:18:05-__init__-DEBUG-Using selector: SelectSelector
2019-18-27 12:18:07-trigger_reload-INFO-D:\Study\School\e2e\app\djangoapp\backend\views.py changed, reloading.
2019-18-27 12:18:07-__init__-DEBUG-Using selector: SelectSelector
2019-18-27 12:18:11-trigger_reload-INFO-D:\Study\School\e2e\app\djangoapp\backend\views.py changed, reloading.
2019-18-27 12:18:11-__init__-DEBUG-Using selector: SelectSelector
2019-18-27 12:18:18-__init__-DEBUG-Using selector: SelectSelector
2019-18-27 12:18:32-trigger_reload-INFO-D:\Study\School\e2e\app\djangoapp\backend\views.py changed, reloading.
2019-18-27 12:18:32-__init__-DEBUG-Using selector: SelectSelector
2019-18-27 12:18:34-log_response-ERROR-Internal Server Error: /apis/user/
Traceback (most recent call last):
  File "C:\Users\Pisho\AppData\Roaming\Python\Python37\site-packages\django\core\handlers\exception.py", line 34, in inner
    response = get_response(request)
  File "C:\Users\Pisho\AppData\Roaming\Python\Python37\site-packages\django\core\handlers\base.py", line 115, in _get_response
    response = self.process_exception_by_middleware(e, request)
  File "C:\Users\Pisho\AppData\Roaming\Python\Python37\site-packages\django\core\handlers\base.py", line 113, in _get_response
    response = wrapped_callback(request, *callback_args, **callback_kwargs)
  File "C:\Users\Pisho\AppData\Roaming\Python\Python37\site-packages\django\views\decorators\csrf.py", line 54, in wrapped_view
    return view_func(*args, **kwargs)
  File "C:\Users\Pisho\AppData\Roaming\Python\Python37\site-packages\django\views\generic\base.py", line 71, in view
    return self.dispatch(request, *args, **kwargs)
  File "C:\Users\Pisho\AppData\Local\Programs\Python\Python37\lib\site-packages\rest_framework\views.py", line 505, in dispatch
    response = self.handle_exception(exc)
  File "C:\Users\Pisho\AppData\Local\Programs\Python\Python37\lib\site-packages\rest_framework\views.py", line 465, in handle_exception
    self.raise_uncaught_exception(exc)
  File "C:\Users\Pisho\AppData\Local\Programs\Python\Python37\lib\site-packages\rest_framework\views.py", line 476, in raise_uncaught_exception
    raise exc
  File "C:\Users\Pisho\AppData\Local\Programs\Python\Python37\lib\site-packages\rest_framework\views.py", line 502, in dispatch
    response = handler(request, *args, **kwargs)
  File "C:\Users\Pisho\AppData\Local\Programs\Python\Python37\lib\site-packages\rest_framework\decorators.py", line 50, in handler
    return func(*args, **kwargs)
TypeError: __init__() takes 1 positional argument but 2 were given
2019-18-27 12:18:40-trigger_reload-INFO-D:\Study\School\e2e\app\djangoapp\backend\views.py changed, reloading.
2019-18-27 12:18:40-__init__-DEBUG-Using selector: SelectSelector
2019-18-27 12:18:43-trigger_reload-INFO-D:\Study\School\e2e\app\djangoapp\backend\views.py changed, reloading.
2019-18-27 12:18:43-__init__-DEBUG-Using selector: SelectSelector
2019-18-27 12:18:54-log_response-ERROR-Internal Server Error: /apis/user/
Traceback (most recent call last):
  File "C:\Users\Pisho\AppData\Roaming\Python\Python37\site-packages\django\core\handlers\exception.py", line 34, in inner
    response = get_response(request)
  File "C:\Users\Pisho\AppData\Roaming\Python\Python37\site-packages\django\core\handlers\base.py", line 115, in _get_response
    response = self.process_exception_by_middleware(e, request)
  File "C:\Users\Pisho\AppData\Roaming\Python\Python37\site-packages\django\core\handlers\base.py", line 113, in _get_response
    response = wrapped_callback(request, *callback_args, **callback_kwargs)
  File "C:\Users\Pisho\AppData\Roaming\Python\Python37\site-packages\django\views\decorators\csrf.py", line 54, in wrapped_view
    return view_func(*args, **kwargs)
  File "C:\Users\Pisho\AppData\Roaming\Python\Python37\site-packages\django\views\generic\base.py", line 71, in view
    return self.dispatch(request, *args, **kwargs)
  File "C:\Users\Pisho\AppData\Local\Programs\Python\Python37\lib\site-packages\rest_framework\views.py", line 505, in dispatch
    response = self.handle_exception(exc)
  File "C:\Users\Pisho\AppData\Local\Programs\Python\Python37\lib\site-packages\rest_framework\views.py", line 465, in handle_exception
    self.raise_uncaught_exception(exc)
  File "C:\Users\Pisho\AppData\Local\Programs\Python\Python37\lib\site-packages\rest_framework\views.py", line 476, in raise_uncaught_exception
    raise exc
  File "C:\Users\Pisho\AppData\Local\Programs\Python\Python37\lib\site-packages\rest_framework\views.py", line 502, in dispatch
    response = handler(request, *args, **kwargs)
  File "C:\Users\Pisho\AppData\Local\Programs\Python\Python37\lib\site-packages\rest_framework\decorators.py", line 50, in handler
    return func(*args, **kwargs)
TypeError: __init__() takes 1 positional argument but 2 were given
2019-19-27 12:19:28-trigger_reload-INFO-D:\Study\School\e2e\app\djangoapp\backend\views.py changed, reloading.
2019-19-27 12:19:28-__init__-DEBUG-Using selector: SelectSelector
2019-19-27 12:19:31-trigger_reload-INFO-D:\Study\School\e2e\app\djangoapp\backend\views.py changed, reloading.
2019-19-27 12:19:31-__init__-DEBUG-Using selector: SelectSelector
2019-46-27 12:46:06-trigger_reload-INFO-D:\Study\School\e2e\app\djangoapp\backend\models.py changed, reloading.
2019-46-27 12:46:06-__init__-DEBUG-Using selector: SelectSelector
2019-46-27 12:46:08-trigger_reload-INFO-D:\Study\School\e2e\app\djangoapp\backend\models.py changed, reloading.
2019-46-27 12:46:08-__init__-DEBUG-Using selector: SelectSelector
2019-46-27 12:46:56-trigger_reload-INFO-D:\Study\School\e2e\app\djangoapp\backend\views.py changed, reloading.
2019-46-27 12:46:56-__init__-DEBUG-Using selector: SelectSelector
2019-46-27 12:46:59-trigger_reload-INFO-D:\Study\School\e2e\app\djangoapp\backend\views.py changed, reloading.
2019-46-27 12:46:59-__init__-DEBUG-Using selector: SelectSelector
2019-57-27 12:57:55-trigger_reload-INFO-D:\Study\School\e2e\app\djangoapp\backend\views.py changed, reloading.
2019-57-27 12:57:55-__init__-DEBUG-Using selector: SelectSelector
